Workbook

Sheet Léeme
A1: Catálogo de partidas Enzyme — Reforma de vivienda (España)
A2: Versión 1 · base de precios: presupuesto Ortega y Gasset 47 (P26018, REV 2) · precios en € sin IVA
A4: Cómo está organizado
A5: • Capítulos por gremio, cada uno referido a un capítulo del Generador de Precios de CYPE (Rehabilitación).
A6: • Un código = una partida con precio unitario. Los códigos no cambian de significado; una especificación nueva lleva código nuevo.
A7: • Todas las partidas son 'todo incluido' (suministro + colocación) en la calidad estándar Enzyme.
A8: • Fase de oferta: solo estándar, sin opciones ni peticiones del cliente. Las alternativas (tarima, PVC, gran altura…) son partidas del catálogo para después del contrato.
A10: Hojas
A11: • Capítulos: estructura y correspondencia con CYPE.
A12: • Partidas: catálogo con precio Enzyme y de dónde sale cada precio.
A13: • Plantillas: estancias tipo. Cantidad = factor × tamaño + fijo.
A14: • Calculadora: estancias y m² → presupuesto por capítulos. Ejemplo con superficies aproximadas; ajústelas.
... A31: • Electricidad por estancia: Las estancias pasan a la medición; las partidas son unitarias (ELE-020 a ELE-090).

Sheet Capítulos
A1: Código | B1: Capítulo | C1: Capítulo CYPE | D1: Orden | E1: Nº partidas
A3: PRE | B3: Actuaciones previas y medios auxiliares | C3: 0 | D3: 10 | E3: =COUNTIF(Partidas!$B:$B,A3) -> 4
A4: DEM | B4: Demoliciones y desmontajes | C4: D | D4: 20 | E4: =COUNTIF(Partidas!$B:$B,A4) -> 12
A5: TAB | B5: Tabiquería y trasdosados | C5: F | D5: 30 | E5: =COUNTIF(Partidas!$B:$B,A5) -> 3
A6: TEC | B6: Falsos techos y molduras | C6: R | D6: 40 | E6: =COUNTIF(Partidas!$B:$B,A6) -> 5
A7: IMP | B7: Aislamientos e impermeabilizaciones | C7: N | D7: 50 | E7: =COUNTIF(Partidas!$B:$B,A7) -> 3
A8: REV | B8: Revestimientos de paredes | C8: R | D8: 60 | E8: =COUNTIF(Partidas!$B:$B,A8) -> 5
A9: PAV | B9: Pavimentos y rodapiés | C9: R | D9: 70 | E9: =COUNTIF(Partidas!$B:$B,A9) -> 6
A10: CEX | B10: Carpintería exterior y protecciones solares | C10: L | D10: 80 | E10: =COUNTIF(Partidas!$B:$B,A10) -> 4
A11: CIN | B11: Carpintería interior y mobiliario a medida | C11: L | D11: 90 | E11: =COUNTIF(Partidas!$B:$B,A11) -> 6
A12: FON | B12: Fontanería y saneamiento | C12: I | D12: 100 | E12: =COUNTIF(Partidas!$B:$B,A12) -> 5
A13: SAN | B13: Sanitarios, grifería y equipamiento de baño | C13: I | D13: 110 | E13: =COUNTIF(Partidas!$B:$B,A13) -> 12
A14: COC | B14: Cocina | C14: S | D14: 120 | E14: =COUNTIF(Partidas!$B:$B,A14) -> 3
... A22: LIM | B22: Limpieza y entrega | C22: H | D22: 200 | E22: =COUNTIF(Partidas!$B:$B,A22) -> 1

Sheet Partidas
A1: Código | B1: Capítulo | C1: Ud | D1: Descripción | E1: Especificación estándar Enzyme | F1: Precio Enzyme (€/ud) | G1: Base del precio | H1: Ref. CYPE | I1: Estado
A3: PRE-010 | B3: PRE | C3: pa | D3: Protección de zonas comunes y elementos que se conservan | E3: Protección de portal, ascensor, rellanos, carpinterías y pavimentos que se conservan durante toda la obra, con retirada al final. | G3: OG47 LFO1 la incluye junto a la limpieza final (ver LIM-010) | I3: =IF(F3="","Sin precio","Con precio") -> Sin precio
A4: PRE-020 | B4: PRE | C4: pa | D4: Comunicación a la comunidad y gestión de ascensor/montacargas | E4: Aviso a la comunidad de propietarios, horarios de obra, reserva y protección de ascensor o montacargas para acopios. | I4: =IF(F4="","Sin precio","Con precio") -> Sin precio
A5: PRE-030 | B5: PRE | C5: pa | D5: Medios de elevación para carpintería exterior | E5: Plataforma elevadora, grúa o medio equivalente para subida de carpinterías y vidrios que no caben por escalera o ascensor, incluso permisos de vía pública. | I5: =IF(F5="","Sin precio","Con precio") -> Sin precio
A6: PRE-040 | B6: PRE | C6: pa | D6: Gestión de licencia o declaración responsable | E6: Tramitación ante el ayuntamiento de la licencia o declaración responsable que corresponda. Tasas e ICIO a cargo de la propiedad, fuera de esta partida. | I6: =IF(F6="","Sin precio","Con precio") -> Sin precio
A7: DEM-010 | B7: DEM | C7: pa | D7: Desmontaje de mobiliario existente | E7: Desmontaje de armarios, muebles de cocina y baño y estanterías, con carga y transporte a contenedor de lo no reutilizable. | F7: 500 | G7: OG47 DMC1 | I7: =IF(F7="","Sin precio","Con precio") -> Con precio
A8: DEM-020 | B8: DEM | C8: ud | D8: Desmontaje de carpintería exterior | E8: Desmontaje de hoja y marco de ventana o balconera existente, con retirada a contenedor y hueco preparado para la nueva carpintería. | F8: 32 | G8: OG47 DCE1 | I8: =IF(F8="","Sin precio","Con precio") -> Con precio
A9: DEM-030 | B9: DEM | C9: m2 | D9: Ajuste de hueco en fachada (ampliación o reducción) | E9: Demolición puntual de fábrica para modificar un hueco, repicado, corte de jambas, recibido y enfoscado de mochetas. Medición por m² de hueco intervenido. | F9: 24 | G9: OG47 DFHV | I9: =IF(F9="","Sin precio","Con precio") -> Con precio
A10: DEM-040 | B10: DEM | C10: m2 | D10: Demolición de tabique de placa de yeso laminado | E10: Demolición de tabique de PYL incluida perfilería y aislamiento, con carga a contenedor. | F10: 16 | G10: OG47 (sin código) | I10: =IF(F10="","Sin precio","Con precio") -> Con precio
A11: DEM-050 | B11: DEM | C11: m2 | D11: Demolición de tabique de ladrillo | E11: Demolición de tabique de ladrillo hueco con revestimientos, con carga a contenedor. | I11: =IF(F11="","Sin precio","Con precio") -> Sin precio
A12: DEM-060 | B12: DEM | C12: m2 | D12: Demolición de falso techo de PYL o escayola | E12: Demolición de falso techo incluida estructura de cuelgue, con carga a contenedor. | F12: 10 | G12: OG47 (sin código) | I12: =IF(F12="","Sin precio","Con precio") -> Con precio
A13: DEM-070 | B13: DEM | C13: ud | D13: Desmontaje de radiador | E13: Desmontaje de radiador, vaciado y purgado del circuito y taponado de tomas. | F13: 60 | G13: OG47 DRAD | I13: =IF(F13="","Sin precio","Con precio") -> Con precio
A14: DEM-080 | B14: DEM | C14: m2 | D14: Levantado de pavimento de madera, laminado o vinílico | E14: Levantado de tarima, parquet, laminado o vinílico con rastreles y adhesivos, con carga a contenedor. | F14: 18 | G14: OG47 LS | I14: =IF(F14="","Sin precio","Con precio") -> Con precio
A15: DEM-090 | B15: DEM | C15: m2 | D15: Picado de alicatado y solado cerámico | E15: Picado de revestimiento cerámico en paredes y suelos hasta soporte, con carga a contenedor. | F15: 28 | G15: OG47 LS (picado) | I15: =IF(F15="","Sin precio","Con precio") -> Con precio
A16: DEM-100 | B16: DEM | C16: ud | D16: Desmontaje de aparato sanitario o grifería | E16: Desmontaje de inodoro, lavabo, bañera, plato o grifería, con anulación de tomas y retirada. | I16: =IF(F16="","Sin precio","Con precio") -> Sin precio
A17: DEM-110 | B17: DEM | C17: ud | D17: Desmontaje de puerta interior | E17: Desmontaje de hoja, cerco y tapajuntas de puerta interior, con retirada. | I17: =IF(F17="","Sin precio","Con precio") -> Sin precio
A18: DEM-120 | B18: DEM | C18: pa | D18: Levantado de instalaciones existentes | E18: Levantado de instalación eléctrica, fontanería y calefacción que se sustituyen, con retirada. | I18: =IF(F18="","Sin precio","Con precio") -> Sin precio
A19: TAB-010 | B19: TAB | C19: m2 | D19: Tabique PYL 2 placas por cara con aislamiento | E19: Tabique de placa de yeso laminado sobre perfilería de 70 mm, 2 placas por cara (hidrófuga en zonas húmedas), lana mineral, juntas tratadas listo para pintar. | F19: 60 | G19: OG47 TP2PA | I19: =IF(F19="","Sin precio","Con precio") -> Con precio
A20: TAB-020 | B20: TAB | C20: m2 | D20: Trasdosado PYL 1 placa sobre perfilería con aislamiento | E20: Trasdosado de una placa sobre perfilería autoportante con lana mineral, juntas tratadas. | F20: 40 | G20: OG47 TA | I20: =IF(F20="","Sin precio","Con precio") -> Con precio
A21: TAB-030 | B21: TAB | C21: m2 | D21: Trasdosado PYL 1 placa directo | E21: Trasdosado directo de placa adherida al paramento con pasta de agarre, juntas tratadas. | F21: 30 | G21: OG47 TA (pegado) | I21: =IF(F21="","Sin precio","Con precio") -> Con precio
A22: TEC-010 | B22: TEC | C22: m2 | D22: Falso techo continuo PYL | E22: Falso techo continuo de placa de yeso laminado tipo N sobre estructura metálica, juntas tratadas listo para pintar. | F22: 30 | G22: OG47 FTYN | I22: =IF(F22="","Sin precio","Con precio") -> Con precio
A23: TEC-020 | B23: TEC | C23: m2 | D23: Falso techo continuo PYL hidrófugo | E23: Falso techo continuo de placa hidrófuga en baños, aseos, cocina y lavandería. | F23: 32 | G23: OG47 FTWA | I23: =IF(F23="","Sin precio","Con precio") -> Con precio
A24: TEC-030 | B24: TEC | C24: m | D24: Candileja o foseado perimetral para LED | E24: Cajeado perimetral en falso techo para tira LED (suministro en ILU), juntas tratadas. | F24: 40 | G24: OG47 CP1 | I24: =IF(F24="","Sin precio","Con precio") -> Con precio
A25: TEC-040 | B25: TEC | C25: m | D25: Moldura decorativa de escayola | E25: Suministro y colocación de moldura de escayola techo-pared, ingletes y juntas, lista para pintar. Modelo estándar. | F25: 20 | G25: OG47 ESC S 10 + ESC I 10 | I25: =IF(F25="","Sin precio","Con precio") -> Con precio
A26: TEC-050 | B26: TEC | C26: ud | D26: Registro en falso techo | E26: Trampilla de registro de PYL para acceso a instalaciones. | I26: =IF(F26="","Sin precio","Con precio") -> Sin precio
A27: IMP-010 | B27: IMP | C27: m2 | D27: Impermeabilización de suelo en zona húmeda | E27: Membrana impermeabilizante bajo solado en baños, aseos y lavandería, con banda perimetral y remate en encuentros. | I27: =IF(F27="","Sin precio","Con precio") -> Sin precio
A28: IMP-020 | B28: IMP | C28: ud | D28: Desagüe lineal y manta impermeable para ducha de obra | E28: Canaleta de desagüe lineal y manta impermeabilizante para ducha a nivel de suelo, suministro e instalación. | F28: 340 | G28: OG47 IDD 180 + IDD 160 | I28: =IF(F28="","Sin precio","Con precio") -> Con precio
A29: IMP-030 | B29: IMP | C29: m2 | D29: Lámina anti-impacto bajo pavimento | E29: Lámina acústica de polietileno reticulado bajo recrecido o pavimento flotante. | I29: =IF(F29="","Sin precio","Con precio") -> Sin precio
A30: REV-010 | B30: REV | C30: m2 | D30: Alicatado de gres porcelánico | E30: Suministro (gama estándar Enzyme) y colocación con adhesivo C2 y doble encolado, rejuntado, cortes e ingletes. Incluye 10 % de desperdicio. | F30: 90 | G30: OG47 PCA 40 + PS 45 × 43/38,9 m² = 89,7 | I30: =IF(F30="","Sin precio","Con precio") -> Con precio
A31: REV-020 | B31: REV | C31: m2 | D31: Enlucido o alisado de paredes | E31: Regularización de paramentos tras demoliciones con guarnecido y enlucido de yeso o alisado, listo para pintar. | I31: =IF(F31="","Sin precio","Con precio") -> Sin precio
A32: REV-030 | B32: REV | C32: m | D32: Moldura de pared tipo boiserie | E32: Suministro y colocación de moldura de PVC o HDPS sobre pared lisa formando paños, lista para pintar. | F32: 20 | G32: OG47 PM 10 + PM 10 | I32: =IF(F32="","Sin precio","Con precio") -> Con precio
A33: REV-040 | B33: REV | C33: m2 | D33: Espejo decorativo en pared | E33: Suministro y colocación de espejo con adhesivo específico y canteado de bordes. | F33: 80 | G33: OG47 OTRO5 (espejos salón) | I33: =IF(F33="","Sin precio","Con precio") -> Con precio
A34: REV-050 | B34: REV | C34: m | D34: Viga decorativa imitación madera | E34: Suministro y colocación de viga decorativa imitación madera con foseado y remates. | F34: 95 | G34: OG47 OTRO5 (vigas) | I34: =IF(F34="","Sin precio","Con precio") -> Con precio
A35: PAV-010 | B35: PAV | C35: m2 | D35: Recrecido de mortero autonivelante | E35: Recrecido con mortero autonivelante para regularizar el soporte, espesor según obra. | F35: 30 | G35: OG47 OTRO1 | I35: =IF(F35="","Sin precio","Con precio") -> Con precio
A36: PAV-020 | B36: PAV | C36: m2 | D36: Solado de gres porcelánico | E36: Suministro (gama estándar Enzyme) y colocación con adhesivo C2, rejuntado y cortes. Incluye 10 % de desperdicio. | F36: 86 | G36: OG47 PCS 35 + PS 45 × 12/10,5 m² = 86,4 | I36: =IF(F36="","Sin precio","Con precio") -> Con precio
A37: PAV-030 | B37: PAV | C37: m2 | D37: Suelo laminado flotante | E37: Suministro (gama estándar Enzyme, AC4) y colocación flotante sobre lámina, remates y juntas de dilatación. Incluye 10 % de desperdicio. | F37: 78 | G37: OG47 PS B 50 × 85/79 m² + PCS 24 = 77,8 (en espiga húngara) | I37: =IF(F37="","Sin precio","Con precio") -> Con precio
A38: PAV-040 | B38: PAV | C38: m2 | D38: Tarima de madera natural | E38: Suministro e instalación por instalador especializado de tarima de madera natural, acabado barnizado o aceitado. | F38: 120 | G38: OG47 PS A | I38: =IF(F38="","Sin precio","Con precio") -> Con precio
A39: PAV-050 | B39: PAV | C39: m2 | D39: Suelo vinílico SPC | E39: Suministro y colocación de suelo vinílico SPC con sistema click. | F39: 54 | G39: OG47 PS C 30 + PCS 24 | I39: =IF(F39="","Sin precio","Con precio") -> Con precio
A40: PAV-060 | B40: PAV | C40: m | D40: Rodapié lacado blanco 20 cm | E40: Suministro y colocación de rodapié blanco de 20 cm con adhesivo y/o clavado, juntas selladas. | F40: 18.75 | G40: OG47 PRE 10,75 + PCR 8 | I40: =IF(F40="","Sin precio","Con precio") -> Con precio
A41: CEX-010 | B41: CEX | C41: ud | D41: Ventana de aluminio con rotura de puente térmico | E41: Suministro y colocación de ventana de aluminio RPT, oscilobatiente, acabado blanco, doble acristalamiento bajo emisivo, herrajes, recibido y sellado. Tamaño medio de vivienda. | F41: 1052 | G41: OG47 OTRO2 A 9.470 € / 9 ventanas | I41: =IF(F41="","Sin precio","Con precio") -> Con precio
...

Sheet Plantillas
A1: Plantilla | B1: Estancia | C1: Tamaño en | D1: Partida | E1: Descripción | F1: Ud | G1: Factor | H1: Fijo | I1: Nota
A3: GEN | B3: Partidas generales de la vivienda | C3: m² útiles de vivienda | D3: PRE-010 | E3: =INDEX(Partidas!$D$2:$D$99,MATCH(D3,Partidas!$A$2:$A$99,0)) -> Protección de zonas comunes y elementos que se conservan | F3: =INDEX(Partidas!$C$2:$C$99,MATCH(D3,Partidas!$A$2:$A$99,0)) -> pa | G3: 0 | H3: 1
A4: GEN | B4: Partidas generales de la vivienda | C4: m² útiles de vivienda | D4: PRE-020 | E4: =INDEX(Partidas!$D$2:$D$99,MATCH(D4,Partidas!$A$2:$A$99,0)) -> Comunicación a la comunidad y gestión de ascensor/montacargas | F4: =INDEX(Partidas!$C$2:$C$99,MATCH(D4,Partidas!$A$2:$A$99,0)) -> pa | G4: 0 | H4: 1
A5: GEN | B5: Partidas generales de la vivienda | C5: m² útiles de vivienda | D5: PRE-040 | E5: =INDEX(Partidas!$D$2:$D$99,MATCH(D5,Partidas!$A$2:$A$99,0)) -> Gestión de licencia o declaración responsable | F5: =INDEX(Partidas!$C$2:$C$99,MATCH(D5,Partidas!$A$2:$A$99,0)) -> pa | G5: 0 | H5: 1
A6: GEN | B6: Partidas generales de la vivienda | C6: m² útiles de vivienda | D6: DEM-010 | E6: =INDEX(Partidas!$D$2:$D$99,MATCH(D6,Partidas!$A$2:$A$99,0)) -> Desmontaje de mobiliario existente | F6: =INDEX(Partidas!$C$2:$C$99,MATCH(D6,Partidas!$A$2:$A$99,0)) -> pa | G6: 0 | H6: 1
A7: GEN | B7: Partidas generales de la vivienda | C7: m² útiles de vivienda | D7: DEM-120 | E7: =INDEX(Partidas!$D$2:$D$99,MATCH(D7,Partidas!$A$2:$A$99,0)) -> Levantado de instalaciones existentes | F7: =INDEX(Partidas!$C$2:$C$99,MATCH(D7,Partidas!$A$2:$A$99,0)) -> pa | G7: 0 | H7: 1
A8: GEN | B8: Partidas generales de la vivienda | C8: m² útiles de vivienda | D8: ELE-010 | E8: =INDEX(Partidas!$D$2:$D$99,MATCH(D8,Partidas!$A$2:$A$99,0)) -> Instalación eléctrica: cuadro, circuitos y boletín | F8: =INDEX(Partidas!$C$2:$C$99,MATCH(D8,Partidas!$A$2:$A$99,0)) -> pa | G8: 0 | H8: 1
A9: GEN | B9: Partidas generales de la vivienda | C9: m² útiles de vivienda | D9: ELE-110 | E9: =INDEX(Partidas!$D$2:$D$99,MATCH(D9,Partidas!$A$2:$A$99,0)) -> Timbre | F9: =INDEX(Partidas!$C$2:$C$99,MATCH(D9,Partidas!$A$2:$A$99,0)) -> ud | G9: 0 | H9: 1
A10: GEN | B10: Partidas generales de la vivienda | C10: m² útiles de vivienda | D10: ELE-130 | E10: =INDEX(Partidas!$D$2:$D$99,MATCH(D10,Partidas!$A$2:$A$99,0)) -> Detector de humo autónomo | F10: =INDEX(Partidas!$C$2:$C$99,MATCH(D10,Partidas!$A$2:$A$99,0)) -> ud | G10: 0 | H10: 2
A11: GEN | B11: Partidas generales de la vivienda | C11: m² útiles de vivienda | D11: AYU-010 | E11: =INDEX(Partidas!$D$2:$D$99,MATCH(D11,Partidas!$A$2:$A$99,0)) -> Ayudas de albañilería a instalaciones | F11: =INDEX(Partidas!$C$2:$C$99,MATCH(D11,Partidas!$A$2:$A$99,0)) -> pa | G11: 0 | H11: 1
A12: GEN | B12: Partidas generales de la vivienda | C12: m² útiles de vivienda | D12: RES-010 | E12: =INDEX(Partidas!$D$2:$D$99,MATCH(D12,Partidas!$A$2:$A$99,0)) -> Contenedor de escombros | F12: =INDEX(Partidas!$C$2:$C$99,MATCH(D12,Partidas!$A$2:$A$99,0)) -> ud | G12: 0.044 | H12: 0 | I12: OG47: 4 contenedores / 91 m²
A13: GEN | B13: Partidas generales de la vivienda | C13: m² útiles de vivienda | D13: RES-020 | E13: =INDEX(Partidas!$D$2:$D$99,MATCH(D13,Partidas!$A$2:$A$99,0)) -> Gestión documental de residuos | F13: =INDEX(Partidas!$C$2:$C$99,MATCH(D13,Partidas!$A$2:$A$99,0)) -> pa | G13: 0 | H13: 1
A14: GEN | B14: Partidas generales de la vivienda | C14: m² útiles de vivienda | D14: SYS-010 | E14: =INDEX(Partidas!$D$2:$D$99,MATCH(D14,Partidas!$A$2:$A$99,0)) -> Seguridad y salud | F14: =INDEX(Partidas!$C$2:$C$99,MATCH(D14,Partidas!$A$2:$A$99,0)) -> pa | G14: 0 | H14: 1
A15: GEN | B15: Partidas generales de la vivienda | C15: m² útiles de vivienda | D15: LIM-010 | E15: =INDEX(Partidas!$D$2:$D$99,MATCH(D15,Partidas!$A$2:$A$99,0)) -> Limpieza de fin de obra | F15: =INDEX(Partidas!$C$2:$C$99,MATCH(D15,Partidas!$A$2:$A$99,0)) -> pa | G15: 0 | H15: 1
A16: DOR | B16: Dormitorio | C16: m² de suelo | D16: PAV-030 | E16: =INDEX(Partidas!$D$2:$D$99,MATCH(D16,Partidas!$A$2:$A$99,0)) -> Suelo laminado flotante | F16: =INDEX(Partidas!$C$2:$C$99,MATCH(D16,Partidas!$A$2:$A$99,0)) -> m2 | G16: 1 | H16: 0
A17: DOR | B17: Dormitorio | C17: m² de suelo | D17: PAV-060 | E17: =INDEX(Partidas!$D$2:$D$99,MATCH(D17,Partidas!$A$2:$A$99,0)) -> Rodapié lacado blanco 20 cm | F17: =INDEX(Partidas!$C$2:$C$99,MATCH(D17,Partidas!$A$2:$A$99,0)) -> m | G17: 0.9 | H17: 0 | I17: OG47: 80 m / 91 m²
A18: DOR | B18: Dormitorio | C18: m² de suelo | D18: TEC-010 | E18: =INDEX(Partidas!$D$2:$D$99,MATCH(D18,Partidas!$A$2:$A$99,0)) -> Falso techo continuo PYL | F18: =INDEX(Partidas!$C$2:$C$99,MATCH(D18,Partidas!$A$2:$A$99,0)) -> m2 | G18: 1 | H18: 0
A19: DOR | B19: Dormitorio | C19: m² de suelo | D19: PIN-010 | E19: =INDEX(Partidas!$D$2:$D$99,MATCH(D19,Partidas!$A$2:$A$99,0)) -> Pintura plástica lisa en paredes | F19: =INDEX(Partidas!$C$2:$C$99,MATCH(D19,Partidas!$A$2:$A$99,0)) -> m2 | G19: 2.4 | H19: 0 | I19: OG47: 220 m² / 91 m²
A20: DOR | B20: Dormitorio | C20: m² de suelo | D20: PIN-020 | E20: =INDEX(Partidas!$D$2:$D$99,MATCH(D20,Partidas!$A$2:$A$99,0)) -> Pintura plástica lisa en techos | F20: =INDEX(Partidas!$C$2:$C$99,MATCH(D20,Partidas!$A$2:$A$99,0)) -> m2 | G20: 1 | H20: 0
A21: DOR | B21: Dormitorio | C21: m² de suelo | D21: ELE-040 | E21: =INDEX(Partidas!$D$2:$D$99,MATCH(D21,Partidas!$A$2:$A$99,0)) -> Punto de luz conmutado | F21: =INDEX(Partidas!$C$2:$C$99,MATCH(D21,Partidas!$A$2:$A$99,0)) -> ud | G21: 0 | H21: 1
A22: DOR | B22: Dormitorio | C22: m² de suelo | D22: ELE-030 | E22: =INDEX(Partidas!$D$2:$D$99,MATCH(D22,Partidas!$A$2:$A$99,0)) -> Punto de luz adicional en el mismo circuito | F22: =INDEX(Partidas!$C$2:$C$99,MATCH(D22,Partidas!$A$2:$A$99,0)) -> ud | G22: 0 | H22: 1
A23: DOR | B23: Dormitorio | C23: m² de suelo | D23: ELE-020 | E23: =INDEX(Partidas!$D$2:$D$99,MATCH(D23,Partidas!$A$2:$A$99,0)) -> Punto de luz sencillo | F23: =INDEX(Partidas!$C$2:$C$99,MATCH(D23,Partidas!$A$2:$A$99,0)) -> ud | G23: 0 | H23: 1
A24: DOR | B24: Dormitorio | C24: m² de suelo | D24: ELE-060 | E24: =INDEX(Partidas!$D$2:$D$99,MATCH(D24,Partidas!$A$2:$A$99,0)) -> Toma de corriente | F24: =INDEX(Partidas!$C$2:$C$99,MATCH(D24,Partidas!$A$2:$A$99,0)) -> ud | G24: 0 | H24: 4
A25: DOR | B25: Dormitorio | C25: m² de suelo | D25: CIN-010 | E25: =INDEX(Partidas!$D$2:$D$99,MATCH(D25,Partidas!$A$2:$A$99,0)) -> Puerta de paso abatible, altura estándar | F25: =INDEX(Partidas!$C$2:$C$99,MATCH(D25,Partidas!$A$2:$A$99,0)) -> ud | G25: 0 | H25: 1
A26: SAL | B26: Salón-comedor | C26: m² de suelo | D26: PAV-030 | E26: =INDEX(Partidas!$D$2:$D$99,MATCH(D26,Partidas!$A$2:$A$99,0)) -> Suelo laminado flotante | F26: =INDEX(Partidas!$C$2:$C$99,MATCH(D26,Partidas!$A$2:$A$99,0)) -> m2 | G26: 1 | H26: 0
A27: SAL | B27: Salón-comedor | C27: m² de suelo | D27: PAV-060 | E27: =INDEX(Partidas!$D$2:$D$99,MATCH(D27,Partidas!$A$2:$A$99,0)) -> Rodapié lacado blanco 20 cm | F27: =INDEX(Partidas!$C$2:$C$99,MATCH(D27,Partidas!$A$2:$A$99,0)) -> m | G27: 0.9 | H27: 0
A28: SAL | B28: Salón-comedor | C28: m² de suelo | D28: TEC-010 | E28: =INDEX(Partidas!$D$2:$D$99,MATCH(D28,Partidas!$A$2:$A$99,0)) -> Falso techo continuo PYL | F28: =INDEX(Partidas!$C$2:$C$99,MATCH(D28,Partidas!$A$2:$A$99,0)) -> m2 | G28: 1 | H28: 0
A29: SAL | B29: Salón-comedor | C29: m² de suelo | D29: PIN-010 | E29: =INDEX(Partidas!$D$2:$D$99,MATCH(D29,Partidas!$A$2:$A$99,0)) -> Pintura plástica lisa en paredes | F29: =INDEX(Partidas!$C$2:$C$99,MATCH(D29,Partidas!$A$2:$A$99,0)) -> m2 | G29: 2.4 | H29: 0
A30: SAL | B30: Salón-comedor | C30: m² de suelo | D30: PIN-020 | E30: =INDEX(Partidas!$D$2:$D$99,MATCH(D30,Partidas!$A$2:$A$99,0)) -> Pintura plástica lisa en techos | F30: =INDEX(Partidas!$C$2:$C$99,MATCH(D30,Partidas!$A$2:$A$99,0)) -> m2 | G30: 1 | H30: 0
A31: SAL | B31: Salón-comedor | C31: m² de suelo | D31: ELE-050 | E31: =INDEX(Partidas!$D$2:$D$99,MATCH(D31,Partidas!$A$2:$A$99,0)) -> Punto de luz de cruce | F31: =INDEX(Partidas!$C$2:$C$99,MATCH(D31,Partidas!$A$2:$A$99,0)) -> ud | G31: 0 | H31: 1
... A45: BAN | B45: Baño completo con ducha | C45: m² de suelo | D45: PAV-020 | E45: =INDEX(Partidas!$D$2:$D$99,MATCH(D45,Partidas!$A$2:$A$99,0)) -> Solado de gres porcelánico | F45: =INDEX(Partidas!$C$2:$C$99,MATCH(D45,Partidas!$A$2:$A$99,0)) -> m2 | G45: 1 | H45: 0
A46: BAN | B46: Baño completo con ducha | C46: m² de suelo | D46: REV-010 | E46: =INDEX(Partidas!$D$2:$D$99,MATCH(D46,Partidas!$A$2:$A$99,0)) -> Alicatado de gres porcelánico | F46: =INDEX(Partidas!$C$2:$C$99,MATCH(D46,Partidas!$A$2:$A$99,0)) -> m2 | G46: 3.7 | H46: 0 | I46: OG47: 38,9 m² alicatado / 10,5 m² suelo húmedo
A47: BAN | B47: Baño completo con ducha | C47: m² de suelo | D47: TEC-020 | E47: =INDEX(Partidas!$D$2:$D$99,MATCH(D47,Partidas!$A$2:$A$99,0)) -> Falso techo continuo PYL hidrófugo | F47: =INDEX(Partidas!$C$2:$C$99,MATCH(D47,Partidas!$A$2:$A$99,0)) -> m2 | G47: 1 | H47: 0
A48: BAN | B48: Baño completo con ducha | C48: m² de suelo | D48: PIN-020 | E48: =INDEX(Partidas!$D$2:$D$99,MATCH(D48,Partidas!$A$2:$A$99,0)) -> Pintura plástica lisa en techos | F48: =INDEX(Partidas!$C$2:$C$99,MATCH(D48,Partidas!$A$2:$A$99,0)) -> m2 | G48: 1 | H48: 0
A49: BAN | B49: Baño completo con ducha | C49: m² de suelo | D49: FON-010 | E49: =INDEX(Partidas!$D$2:$D$99,MATCH(D49,Partidas!$A$2:$A$99,0)) -> Punto de agua fría y caliente | F49: =INDEX(Partidas!$C$2:$C$99,MATCH(D49,Partidas!$A$2:$A$99,0)) -> ud | G49: 0 | H49: 4.5 | I49: lavabo 2 + ducha 2 + inodoro 0,5
A50: BAN | B50: Baño completo con ducha | C50: m² de suelo | D50: FON-020 | E50: =INDEX(Partidas!$D$2:$D$99,MATCH(D50,Partidas!$A$2:$A$99,0)) -> Punto de desagüe | F50: =INDEX(Partidas!$C$2:$C$99,MATCH(D50,Partidas!$A$2:$A$99,0)) -> ud | G50: 0 | H50: 3
A51: BAN | B51: Baño completo con ducha | C51: m² de suelo | D51: FON-030 | E51: =INDEX(Partidas!$D$2:$D$99,MATCH(D51,Partidas!$A$2:$A$99,0)) -> Bote sifónico | F51: =INDEX(Partidas!$C$2:$C$99,MATCH(D51,Partidas!$A$2:$A$99,0)) -> ud | G51: 0 | H51: 1
A52: BAN | B52: Baño completo con ducha | C52: m² de suelo | D52: FON-040 | E52: =INDEX(Partidas!$D$2:$D$99,MATCH(D52,Partidas!$A$2:$A$99,0)) -> Llave de corte por estancia húmeda | F52: =INDEX(Partidas!$C$2:$C$99,MATCH(D52,Partidas!$A$2:$A$99,0)) -> ud | G52: 0 | H52: 1
A53: BAN | B53: Baño completo con ducha | C53: m² de suelo | D53: SAN-010 | E53: =INDEX(Partidas!$D$2:$D$99,MATCH(D53,Partidas!$A$2:$A$99,0)) -> Plato de ducha | F53: =INDEX(Partidas!$C$2:$C$99,MATCH(D53,Partidas!$A$2:$A$99,0)) -> ud | G53: 0 | H53: 1
A54: BAN | B54: Baño completo con ducha | C54: m² de suelo | D54: SAN-030 | E54: =INDEX(Partidas!$D$2:$D$99,MATCH(D54,Partidas!$A$2:$A$99,0)) -> Inodoro suspendido con bastidor | F54: =INDEX(Partidas!$C$2:$C$99,MATCH(D54,Partidas!$A$2:$A$99,0)) -> ud | G54: 0 | H54: 1
...

Sheet Calculadora
A1: Calculadora de oferta — calidad estándar Enzyme
A2: Rellene en azul: nombre de estancia, plantilla y tamaño (m², o nº de ventanas para VEN). Ejemplo con superficies aproximadas de Ortega y Gasset 47; ajústelas.
A4: Estancia | E4: Vivienda | F4: Salón-comedor | G4: Dormitorio principal | H4: Dormitorio 2 | I4: Dormitorio 3 | J4: Pasillo | K4: Hall | L4: Cocina | M4: Lavandería | N4: Baño principal | O4: Baño 2 | P4: Ventanas
A5: Plantilla | E5: GEN | F5: SAL | G5: DOR | H5: DOR | I5: DOR | J5: PAS | K5: PAS | L5: COC | M5: LAV | N5: BAN | O5: BAN | P5: VEN
A6: Tamaño | E6: 91 | F6: 24 | G6: 15 | H6: 10 | I6: 10 | J6: 7 | K6: 4 | L6: 9 | M6: 3 | N6: 5 | O6: 4 | P6: 9
A8: Código | B8: Cap. | C8: Descripción | D8: Ud | E8: =E4&"" -> Vivienda | F8: =F4&"" -> Salón-comedor | G8: =G4&"" -> Dormitorio principal | H8: =H4&"" -> Dormitorio 2 | I8: =I4&"" -> Dormitorio 3 | J8: =J4&"" -> Pasillo | K8: =K4&"" -> Hall | L8: =L4&"" -> Cocina | ... R8: =R4&"" | S8: Cantidad | T8: Precio (€/ud) | U8: Importe (€)
A9: PRE | C9: Actuaciones previas y medios auxiliares | U9: =SUM(U10:U13) -> 0
A10: PRE-010 | B10: PRE | C10: =INDEX(Partidas!$D$2:$D$99,MATCH(A10,Partidas!$A$2:$A$99,0)) -> Protección de zonas comunes y elementos que se conservan | D10: =INDEX(Partidas!$C$2:$C$99,MATCH(A10,Partidas!$A$2:$A$99,0)) -> pa | E10: =IF(E$5="",0,SUMPRODUCT((Plantillas!$A$2:$A$114=E$5)*(Plantillas!$D$2:$D$114=$A10)*(Plantillas!$G$2:$G$114*N(E$6)+Plantillas!$H$2:$H$114))) -> 1 | F10: =IF(F$5="",0,SUMPRODUCT((Plantillas!$A$2:$A$114=F$5)*(Plantillas!$D$2:$D$114=$A10)*(Plantillas!$G$2:$G$114*N(F$6)+Plantillas!$H$2:$H$114))) -> 0 | G10: =IF(G$5="",0,SUMPRODUCT((Plantillas!$A$2:$A$114=G$5)*(Plantillas!$D$2:$D$114=$A10)*(Plantillas!$G$2:$G$114*N(G$6)+Plantillas!$H$2:$H$114))) -> 0 | H10: =IF(H$5="",0,SUMPRODUCT((Plantillas!$A$2:$A$114=H$5)*(Plantillas!$D$2:$D$114=$A10)*(Plantillas!$G$2:$G$114*N(H$6)+Plantillas!$H$2:$H$114))) -> 0 | I10: =IF(I$5="",0,SUMPRODUCT((Plantillas!$A$2:$A$114=I$5)*(Plantillas!$D$2:$D$114=$A10)*(Plantillas!$G$2:$G$114*N(I$6)+Plantillas!$H$2:$H$114))) -> 0 | J10: =IF(J$5="",0,SUMPRODUCT((Plantillas!$A$2:$A$114=J$5)*(Plantillas!$D$2:$D$114=$A10)*(Plantillas!$G$2:$G$114*N(J$6)+Plantillas!$H$2:$H$114))) -> 0 | K10: =IF(K$5="",0,SUMPRODUCT((Plantillas!$A$2:$A$114=K$5)*(Plantillas!$D$2:$D$114=$A10)*(Plantillas!$G$2:$G$114*N(K$6)+Plantillas!$H$2:$H$114))) -> 0 | L10: =IF(L$5="",0,SUMPRODUCT((Plantillas!$A$2:$A$114=L$5)*(Plantillas!$D$2:$D$114=$A10)*(Plantillas!$G$2:$G$114*N(L$6)+Plantillas!$H$2:$H$114))) -> 0 | ... R10: =IF(R$5="",0,SUMPRODUCT((Plantillas!$A$2:$A$114=R$5)*(Plantillas!$D$2:$D$114=$A10)*(Plantillas!$G$2:$G$114*N(R$6)+Plantillas!$H$2:$H$114))) -> 0 | S10: =SUM(E10:R10) -> 1 | T10: =IF(INDEX(Partidas!$F$2:$F$99,MATCH(A10,Partidas!$A$2:$A$99,0))="","",INDEX(Partidas!$F$2:$F$99,MATCH(A10,Partidas!$A$2:$A$99,0))) | U10: =IF(T10="",0,S10*T10) -> 0
A11: PRE-020 | B11: PRE | C11: =INDEX(Partidas!$D$2:$D$99,MATCH(A11,Partidas!$A$2:$A$99,0)) -> Comunicación a la comunidad y gestión de ascensor/montacargas | D11: =INDEX(Partidas!$C$2:$C$99,MATCH(A11,Partidas!$A$2:$A$99,0)) -> pa | E11: =IF(E$5="",0,SUMPRODUCT((Plantillas!$A$2:$A$114=E$5)*(Plantillas!$D$2:$D$114=$A11)*(Plantillas!$G$2:$G$114*N(E$6)+Plantillas!$H$2:$H$114))) -> 1 | F11: =IF(F$5="",0,SUMPRODUCT((Plantillas!$A$2:$A$114=F$5)*(Plantillas!$D$2:$D$114=$A11)*(Plantillas!$G$2:$G$114*N(F$6)+Plantillas!$H$2:$H$114))) -> 0 | G11: =IF(G$5="",0,SUMPRODUCT((Plantillas!$A$2:$A$114=G$5)*(Plantillas!$D$2:$D$114=$A11)*(Plantillas!$G$2:$G$114*N(G$6)+Plantillas!$H$2:$H$114))) -> 0 | H11: =IF(H$5="",0,SUMPRODUCT((Plantillas!$A$2:$A$114=H$5)*(Plantillas!$D$2:$D$114=$A11)*(Plantillas!$G$2:$G$114*N(H$6)+Plantillas!$H$2:$H$114))) -> 0 | I11: =IF(I$5="",0,SUMPRODUCT((Plantillas!$A$2:$A$114=I$5)*(Plantillas!$D$2:$D$114=$A11)*(Plantillas!$G$2:$G$114*N(I$6)+Plantillas!$H$2:$H$114))) -> 0 | J11: =IF(J$5="",0,SUMPRODUCT((Plantillas!$A$2:$A$114=J$5)*(Plantillas!$D$2:$D$114=$A11)*(Plantillas!$G$2:$G$114*N(J$6)+Plantillas!$H$2:$H$114))) -> 0 | K11: =IF(K$5="",0,SUMPRODUCT((Plantillas!$A$2:$A$114=K$5)*(Plantillas!$D$2:$D$114=$A11)*(Plantillas!$G$2:$G$114*N(K$6)+Plantillas!$H$2:$H$114))) -> 0 | L11: =IF(L$5="",0,SUMPRODUCT((Plantillas!$A$2:$A$114=L$5)*(Plantillas!$D$2:$D$114=$A11)*(Plantillas!$G$2:$G$114*N(L$6)+Plantillas!$H$2:$H$114))) -> 0 | ... R11: =IF(R$5="",0,SUMPRODUCT((Plantillas!$A$2:$A$114=R$5)*(Plantillas!$D$2:$D$114=$A11)*(Plantillas!$G$2:$G$114*N(R$6)+Plantillas!$H$2:$H$114))) -> 0 | S11: =SUM(E11:R11) -> 1 | T11: =IF(INDEX(Partidas!$F$2:$F$99,MATCH(A11,Partidas!$A$2:$A$99,0))="","",INDEX(Partidas!$F$2:$F$99,MATCH(A11,Partidas!$A$2:$A$99,0))) | U11: =IF(T11="",0,S11*T11) -> 0
A12: PRE-030 | B12: PRE | C12: =INDEX(Partidas!$D$2:$D$99,MATCH(A12,Partidas!$A$2:$A$99,0)) -> Medios de elevación para carpintería exterior | D12: =INDEX(Partidas!$C$2:$C$99,MATCH(A12,Partidas!$A$2:$A$99,0)) -> pa | E12: =IF(E$5="",0,SUMPRODUCT((Plantillas!$A$2:$A$114=E$5)*(Plantillas!$D$2:$D$114=$A12)*(Plantillas!$G$2:$G$114*N(E$6)+Plantillas!$H$2:$H$114))) -> 0 | F12: =IF(F$5="",0,SUMPRODUCT((Plantillas!$A$2:$A$114=F$5)*(Plantillas!$D$2:$D$114=$A12)*(Plantillas!$G$2:$G$114*N(F$6)+Plantillas!$H$2:$H$114))) -> 0 | G12: =IF(G$5="",0,SUMPRODUCT((Plantillas!$A$2:$A$114=G$5)*(Plantillas!$D$2:$D$114=$A12)*(Plantillas!$G$2:$G$114*N(G$6)+Plantillas!$H$2:$H$114))) -> 0 | H12: =IF(H$5="",0,SUMPRODUCT((Plantillas!$A$2:$A$114=H$5)*(Plantillas!$D$2:$D$114=$A12)*(Plantillas!$G$2:$G$114*N(H$6)+Plantillas!$H$2:$H$114))) -> 0 | I12: =IF(I$5="",0,SUMPRODUCT((Plantillas!$A$2:$A$114=I$5)*(Plantillas!$D$2:$D$114=$A12)*(Plantillas!$G$2:$G$114*N(I$6)+Plantillas!$H$2:$H$114))) -> 0 | J12: =IF(J$5="",0,SUMPRODUCT((Plantillas!$A$2:$A$114=J$5)*(Plantillas!$D$2:$D$114=$A12)*(Plantillas!$G$2:$G$114*N(J$6)+Plantillas!$H$2:$H$114))) -> 0 | K12: =IF(K$5="",0,SUMPRODUCT((Plantillas!$A$2:$A$114=K$5)*(Plantillas!$D$2:$D$114=$A12)*(Plantillas!$G$2:$G$114*N(K$6)+Plantillas!$H$2:$H$114))) -> 0 | L12: =IF(L$5="",0,SUMPRODUCT((Plantillas!$A$2:$A$114=L$5)*(Plantillas!$D$2:$D$114=$A12)*(Plantillas!$G$2:$G$114*N(L$6)+Plantillas!$H$2:$H$114))) -> 0 | ... R12: =IF(R$5="",0,SUMPRODUCT((Plantillas!$A$2:$A$114=R$5)*(Plantillas!$D$2:$D$114=$A12)*(Plantillas!$G$2:$G$114*N(R$6)+Plantillas!$H$2:$H$114))) -> 0 | S12: =SUM(E12:R12) -> 1 | T12: =IF(INDEX(Partidas!$F$2:$F$99,MATCH(A12,Partidas!$A$2:$A$99,0))="","",INDEX(Partidas!$F$2:$F$99,MATCH(A12,Partidas!$A$2:$A$99,0))) | U12: =IF(T12="",0,S12*T12) -> 0
A13: PRE-040 | B13: PRE | C13: =INDEX(Partidas!$D$2:$D$99,MATCH(A13,Partidas!$A$2:$A$99,0)) -> Gestión de licencia o declaración responsable | D13: =INDEX(Partidas!$C$2:$C$99,MATCH(A13,Partidas!$A$2:$A$99,0)) -> pa | E13: =IF(E$5="",0,SUMPRODUCT((Plantillas!$A$2:$A$114=E$5)*(Plantillas!$D$2:$D$114=$A13)*(Plantillas!$G$2:$G$114*N(E$6)+Plantillas!$H$2:$H$114))) -> 1 | F13: =IF(F$5="",0,SUMPRODUCT((Plantillas!$A$2:$A$114=F$5)*(Plantillas!$D$2:$D$114=$A13)*(Plantillas!$G$2:$G$114*N(F$6)+Plantillas!$H$2:$H$114))) -> 0 | G13: =IF(G$5="",0,SUMPRODUCT((Plantillas!$A$2:$A$114=G$5)*(Plantillas!$D$2:$D$114=$A13)*(Plantillas!$G$2:$G$114*N(G$6)+Plantillas!$H$2:$H$114))) -> 0 | H13: =IF(H$5="",0,SUMPRODUCT((Plantillas!$A$2:$A$114=H$5)*(Plantillas!$D$2:$D$114=$A13)*(Plantillas!$G$2:$G$114*N(H$6)+Plantillas!$H$2:$H$114))) -> 0 | I13: =IF(I$5="",0,SUMPRODUCT((Plantillas!$A$2:$A$114=I$5)*(Plantillas!$D$2:$D$114=$A13)*(Plantillas!$G$2:$G$114*N(I$6)+Plantillas!$H$2:$H$114))) -> 0 | J13: =IF(J$5="",0,SUMPRODUCT((Plantillas!$A$2:$A$114=J$5)*(Plantillas!$D$2:$D$114=$A13)*(Plantillas!$G$2:$G$114*N(J$6)+Plantillas!$H$2:$H$114))) -> 0 | K13: =IF(K$5="",0,SUMPRODUCT((Plantillas!$A$2:$A$114=K$5)*(Plantillas!$D$2:$D$114=$A13)*(Plantillas!$G$2:$G$114*N(K$6)+Plantillas!$H$2:$H$114))) -> 0 | L13: =IF(L$5="",0,SUMPRODUCT((Plantillas!$A$2:$A$114=L$5)*(Plantillas!$D$2:$D$114=$A13)*(Plantillas!$G$2:$G$114*N(L$6)+Plantillas!$H$2:$H$114))) -> 0 | ... R13: =IF(R$5="",0,SUMPRODUCT((Plantillas!$A$2:$A$114=R$5)*(Plantillas!$D$2:$D$114=$A13)*(Plantillas!$G$2:$G$114*N(R$6)+Plantillas!$H$2:$H$114))) -> 0 | S13: =SUM(E13:R13) -> 1 | T13: =IF(INDEX(Partidas!$F$2:$F$99,MATCH(A13,Partidas!$A$2:$A$99,0))="","",INDEX(Partidas!$F$2:$F$99,MATCH(A13,Partidas!$A$2:$A$99,0))) | U13: =IF(T13="",0,S13*T13) -> 0
A14: DEM | C14: Demoliciones y desmontajes | U14: =SUM(U15:U26) -> 788
A15: DEM-010 | B15: DEM | C15: =INDEX(Partidas!$D$2:$D$99,MATCH(A15,Partidas!$A$2:$A$99,0)) -> Desmontaje de mobiliario existente | D15: =INDEX(Partidas!$C$2:$C$99,MATCH(A15,Partidas!$A$2:$A$99,0)) -> pa | E15: =IF(E$5="",0,SUMPRODUCT((Plantillas!$A$2:$A$114=E$5)*(Plantillas!$D$2:$D$114=$A15)*(Plantillas!$G$2:$G$114*N(E$6)+Plantillas!$H$2:$H$114))) -> 1 | F15: =IF(F$5="",0,SUMPRODUCT((Plantillas!$A$2:$A$114=F$5)*(Plantillas!$D$2:$D$114=$A15)*(Plantillas!$G$2:$G$114*N(F$6)+Plantillas!$H$2:$H$114))) -> 0 | G15: =IF(G$5="",0,SUMPRODUCT((Plantillas!$A$2:$A$114=G$5)*(Plantillas!$D$2:$D$114=$A15)*(Plantillas!$G$2:$G$114*N(G$6)+Plantillas!$H$2:$H$114))) -> 0 | H15: =IF(H$5="",0,SUMPRODUCT((Plantillas!$A$2:$A$114=H$5)*(Plantillas!$D$2:$D$114=$A15)*(Plantillas!$G$2:$G$114*N(H$6)+Plantillas!$H$2:$H$114))) -> 0 | I15: =IF(I$5="",0,SUMPRODUCT((Plantillas!$A$2:$A$114=I$5)*(Plantillas!$D$2:$D$114=$A15)*(Plantillas!$G$2:$G$114*N(I$6)+Plantillas!$H$2:$H$114))) -> 0 | J15: =IF(J$5="",0,SUMPRODUCT((Plantillas!$A$2:$A$114=J$5)*(Plantillas!$D$2:$D$114=$A15)*(Plantillas!$G$2:$G$114*N(J$6)+Plantillas!$H$2:$H$114))) -> 0 | K15: =IF(K$5="",0,SUMPRODUCT((Plantillas!$A$2:$A$114=K$5)*(Plantillas!$D$2:$D$114=$A15)*(Plantillas!$G$2:$G$114*N(K$6)+Plantillas!$H$2:$H$114))) -> 0 | L15: =IF(L$5="",0,SUMPRODUCT((Plantillas!$A$2:$A$114=L$5)*(Plantillas!$D$2:$D$114=$A15)*(Plantillas!$G$2:$G$114*N(L$6)+Plantillas!$H$2:$H$114))) -> 0 | ... R15: =IF(R$5="",0,SUMPRODUCT((Plantillas!$A$2:$A$114=R$5)*(Plantillas!$D$2:$D$114=$A15)*(Plantillas!$G$2:$G$114*N(R$6)+Plantillas!$H$2:$H$114))) -> 0 | S15: =SUM(E15:R15) -> 1 | T15: =IF(INDEX(Partidas!$F$2:$F$99,MATCH(A15,Partidas!$A$2:$A$99,0))="","",INDEX(Partidas!$F$2:$F$99,MATCH(A15,Partidas!$A$2:$A$99,0))) -> 500 | U15: =IF(T15="",0,S15*T15) -> 500
A16: DEM-020 | B16: DEM | C16: =INDEX(Partidas!$D$2:$D$99,MATCH(A16,Partidas!$A$2:$A$99,0)) -> Desmontaje de carpintería exterior | D16: =INDEX(Partidas!$C$2:$C$99,MATCH(A16,Partidas!$A$2:$A$99,0)) -> ud | E16: =IF(E$5="",0,SUMPRODUCT((Plantillas!$A$2:$A$114=E$5)*(Plantillas!$D$2:$D$114=$A16)*(Plantillas!$G$2:$G$114*N(E$6)+Plantillas!$H$2:$H$114))) -> 0 | F16: =IF(F$5="",0,SUMPRODUCT((Plantillas!$A$2:$A$114=F$5)*(Plantillas!$D$2:$D$114=$A16)*(Plantillas!$G$2:$G$114*N(F$6)+Plantillas!$H$2:$H$114))) -> 0 | G16: =IF(G$5="",0,SUMPRODUCT((Plantillas!$A$2:$A$114=G$5)*(Plantillas!$D$2:$D$114=$A16)*(Plantillas!$G$2:$G$114*N(G$6)+Plantillas!$H$2:$H$114))) -> 0 | H16: =IF(H$5="",0,SUMPRODUCT((Plantillas!$A$2:$A$114=H$5)*(Plantillas!$D$2:$D$114=$A16)*(Plantillas!$G$2:$G$114*N(H$6)+Plantillas!$H$2:$H$114))) -> 0 | I16: =IF(I$5="",0,SUMPRODUCT((Plantillas!$A$2:$A$114=I$5)*(Plantillas!$D$2:$D$114=$A16)*(Plantillas!$G$2:$G$114*N(I$6)+Plantillas!$H$2:$H$114))) -> 0 | J16: =IF(J$5="",0,SUMPRODUCT((Plantillas!$A$2:$A$114=J$5)*(Plantillas!$D$2:$D$114=$A16)*(Plantillas!$G$2:$G$114*N(J$6)+Plantillas!$H$2:$H$114))) -> 0 | K16: =IF(K$5="",0,SUMPRODUCT((Plantillas!$A$2:$A$114=K$5)*(Plantillas!$D$2:$D$114=$A16)*(Plantillas!$G$2:$G$114*N(K$6)+Plantillas!$H$2:$H$114))) -> 0 | L16: =IF(L$5="",0,SUMPRODUCT((Plantillas!$A$2:$A$114=L$5)*(Plantillas!$D$2:$D$114=$A16)*(Plantillas!$G$2:$G$114*N(L$6)+Plantillas!$H$2:$H$114))) -> 0 | ... R16: =IF(R$5="",0,SUMPRODUCT((Plantillas!$A$2:$A$114=R$5)*(Plantillas!$D$2:$D$114=$A16)*(Plantillas!$G$2:$G$114*N(R$6)+Plantillas!$H$2:$H$114))) -> 0 | S16: =SUM(E16:R16) -> 9 | T16: =IF(INDEX(Partidas!$F$2:$F$99,MATCH(A16,Partidas!$A$2:$A$99,0))="","",INDEX(Partidas!$F$2:$F$99,MATCH(A16,Partidas!$A$2:$A$99,0))) -> 32 | U16: =IF(T16="",0,S16*T16) -> 288
A17: DEM-030 | B17: DEM | C17: =INDEX(Partidas!$D$2:$D$99,MATCH(A17,Partidas!$A$2:$A$99,0)) -> Ajuste de hueco en fachada (ampliación o reducción) | D17: =INDEX(Partidas!$C$2:$C$99,MATCH(A17,Partidas!$A$2:$A$99,0)) -> m2 | E17: =IF(E$5="",0,SUMPRODUCT((Plantillas!$A$2:$A$114=E$5)*(Plantillas!$D$2:$D$114=$A17)*(Plantillas!$G$2:$G$114*N(E$6)+Plantillas!$H$2:$H$114))) -> 0 | F17: =IF(F$5="",0,SUMPRODUCT((Plantillas!$A$2:$A$114=F$5)*(Plantillas!$D$2:$D$114=$A17)*(Plantillas!$G$2:$G$114*N(F$6)+Plantillas!$H$2:$H$114))) -> 0 | G17: =IF(G$5="",0,SUMPRODUCT((Plantillas!$A$2:$A$114=G$5)*(Plantillas!$D$2:$D$114=$A17)*(Plantillas!$G$2:$G$114*N(G$6)+Plantillas!$H$2:$H$114))) -> 0 | H17: =IF(H$5="",0,SUMPRODUCT((Plantillas!$A$2:$A$114=H$5)*(Plantillas!$D$2:$D$114=$A17)*(Plantillas!$G$2:$G$114*N(H$6)+Plantillas!$H$2:$H$114))) -> 0 | I17: =IF(I$5="",0,SUMPRODUCT((Plantillas!$A$2:$A$114=I$5)*(Plantillas!$D$2:$D$114=$A17)*(Plantillas!$G$2:$G$114*N(I$6)+Plantillas!$H$2:$H$114))) -> 0 | J17: =IF(J$5="",0,SUMPRODUCT((Plantillas!$A$2:$A$114=J$5)*(Plantillas!$D$2:$D$114=$A17)*(Plantillas!$G$2:$G$114*N(J$6)+Plantillas!$H$2:$H$114))) -> 0 | K17: =IF(K$5="",0,SUMPRODUCT((Plantillas!$A$2:$A$114=K$5)*(Plantillas!$D$2:$D$114=$A17)*(Plantillas!$G$2:$G$114*N(K$6)+Plantillas!$H$2:$H$114))) -> 0 | L17: =IF(L$5="",0,SUMPRODUCT((Plantillas!$A$2:$A$114=L$5)*(Plantillas!$D$2:$D$114=$A17)*(Plantillas!$G$2:$G$114*N(L$6)+Plantillas!$H$2:$H$114))) -> 0 | ... R17: =IF(R$5="",0,SUMPRODUCT((Plantillas!$A$2:$A$114=R$5)*(Plantillas!$D$2:$D$114=$A17)*(Plantillas!$G$2:$G$114*N(R$6)+Plantillas!$H$2:$H$114))) -> 0 | S17: =SUM(E17:R17) -> 0 | T17: =IF(INDEX(Partidas!$F$2:$F$99,MATCH(A17,Partidas!$A$2:$A$99,0))="","",INDEX(Partidas!$F$2:$F$99,MATCH(A17,Partidas!$A$2:$A$99,0))) -> 24 | U17: =IF(T17="",0,S17*T17) -> 0
A18: DEM-040 | B18: DEM | C18: =INDEX(Partidas!$D$2:$D$99,MATCH(A18,Partidas!$A$2:$A$99,0)) -> Demolición de tabique de placa de yeso laminado | D18: =INDEX(Partidas!$C$2:$C$99,MATCH(A18,Partidas!$A$2:$A$99,0)) -> m2 | E18: =IF(E$5="",0,SUMPRODUCT((Plantillas!$A$2:$A$114=E$5)*(Plantillas!$D$2:$D$114=$A18)*(Plantillas!$G$2:$G$114*N(E$6)+Plantillas!$H$2:$H$114))) -> 0 | F18: =IF(F$5="",0,SUMPRODUCT((Plantillas!$A$2:$A$114=F$5)*(Plantillas!$D$2:$D$114=$A18)*(Plantillas!$G$2:$G$114*N(F$6)+Plantillas!$H$2:$H$114))) -> 0 | G18: =IF(G$5="",0,SUMPRODUCT((Plantillas!$A$2:$A$114=G$5)*(Plantillas!$D$2:$D$114=$A18)*(Plantillas!$G$2:$G$114*N(G$6)+Plantillas!$H$2:$H$114))) -> 0 | H18: =IF(H$5="",0,SUMPRODUCT((Plantillas!$A$2:$A$114=H$5)*(Plantillas!$D$2:$D$114=$A18)*(Plantillas!$G$2:$G$114*N(H$6)+Plantillas!$H$2:$H$114))) -> 0 | I18: =IF(I$5="",0,SUMPRODUCT((Plantillas!$A$2:$A$114=I$5)*(Plantillas!$D$2:$D$114=$A18)*(Plantillas!$G$2:$G$114*N(I$6)+Plantillas!$H$2:$H$114))) -> 0 | J18: =IF(J$5="",0,SUMPRODUCT((Plantillas!$A$2:$A$114=J$5)*(Plantillas!$D$2:$D$114=$A18)*(Plantillas!$G$2:$G$114*N(J$6)+Plantillas!$H$2:$H$114))) -> 0 | K18: =IF(K$5="",0,SUMPRODUCT((Plantillas!$A$2:$A$114=K$5)*(Plantillas!$D$2:$D$114=$A18)*(Plantillas!$G$2:$G$114*N(K$6)+Plantillas!$H$2:$H$114))) -> 0 | L18: =IF(L$5="",0,SUMPRODUCT((Plantillas!$A$2:$A$114=L$5)*(Plantillas!$D$2:$D$114=$A18)*(Plantillas!$G$2:$G$114*N(L$6)+Plantillas!$H$2:$H$114))) -> 0 | ... R18: =IF(R$5="",0,SUMPRODUCT((Plantillas!$A$2:$A$114=R$5)*(Plantillas!$D$2:$D$114=$A18)*(Plantillas!$G$2:$G$114*N(R$6)+Plantillas!$H$2:$H$114))) -> 0 | S18: =SUM(E18:R18) -> 0 | T18: =IF(INDEX(Partidas!$F$2:$F$99,MATCH(A18,Partidas!$A$2:$A$99,0))="","",INDEX(Partidas!$F$2:$F$99,MATCH(A18,Partidas!$A$2:$A$99,0))) -> 16 | U18: =IF(T18="",0,S18*T18) -> 0
A19: DEM-050 | B19: DEM | C19: =INDEX(Partidas!$D$2:$D$99,MATCH(A19,Partidas!$A$2:$A$99,0)) -> Demolición de tabique de ladrillo | D19: =INDEX(Partidas!$C$2:$C$99,MATCH(A19,Partidas!$A$2:$A$99,0)) -> m2 | E19: =IF(E$5="",0,SUMPRODUCT((Plantillas!$A$2:$A$114=E$5)*(Plantillas!$D$2:$D$114=$A19)*(Plantillas!$G$2:$G$114*N(E$6)+Plantillas!$H$2:$H$114))) -> 0 | F19: =IF(F$5="",0,SUMPRODUCT((Plantillas!$A$2:$A$114=F$5)*(Plantillas!$D$2:$D$114=$A19)*(Plantillas!$G$2:$G$114*N(F$6)+Plantillas!$H$2:$H$114))) -> 0 | G19: =IF(G$5="",0,SUMPRODUCT((Plantillas!$A$2:$A$114=G$5)*(Plantillas!$D$2:$D$114=$A19)*(Plantillas!$G$2:$G$114*N(G$6)+Plantillas!$H$2:$H$114))) -> 0 | H19: =IF(H$5="",0,SUMPRODUCT((Plantillas!$A$2:$A$114=H$5)*(Plantillas!$D$2:$D$114=$A19)*(Plantillas!$G$2:$G$114*N(H$6)+Plantillas!$H$2:$H$114))) -> 0 | I19: =IF(I$5="",0,SUMPRODUCT((Plantillas!$A$2:$A$114=I$5)*(Plantillas!$D$2:$D$114=$A19)*(Plantillas!$G$2:$G$114*N(I$6)+Plantillas!$H$2:$H$114))) -> 0 | J19: =IF(J$5="",0,SUMPRODUCT((Plantillas!$A$2:$A$114=J$5)*(Plantillas!$D$2:$D$114=$A19)*(Plantillas!$G$2:$G$114*N(J$6)+Plantillas!$H$2:$H$114))) -> 0 | K19: =IF(K$5="",0,SUMPRODUCT((Plantillas!$A$2:$A$114=K$5)*(Plantillas!$D$2:$D$114=$A19)*(Plantillas!$G$2:$G$114*N(K$6)+Plantillas!$H$2:$H$114))) -> 0 | L19: =IF(L$5="",0,SUMPRODUCT((Plantillas!$A$2:$A$114=L$5)*(Plantillas!$D$2:$D$114=$A19)*(Plantillas!$G$2:$G$114*N(L$6)+Plantillas!$H$2:$H$114))) -> 0 | ... R19: =IF(R$5="",0,SUMPRODUCT((Plantillas!$A$2:$A$114=R$5)*(Plantillas!$D$2:$D$114=$A19)*(Plantillas!$G$2:$G$114*N(R$6)+Plantillas!$H$2:$H$114))) -> 0 | S19: =SUM(E19:R19) -> 0 | T19: =IF(INDEX(Partidas!$F$2:$F$99,MATCH(A19,Partidas!$A$2:$A$99,0))="","",INDEX(Partidas!$F$2:$F$99,MATCH(A19,Partidas!$A$2:$A$99,0))) | U19: =IF(T19="",0,S19*T19) -> 0
A20: DEM-060 | B20: DEM | C20: =INDEX(Partidas!$D$2:$D$99,MATCH(A20,Partidas!$A$2:$A$99,0)) -> Demolición de falso techo de PYL o escayola | D20: =INDEX(Partidas!$C$2:$C$99,MATCH(A20,Partidas!$A$2:$A$99,0)) -> m2 | E20: =IF(E$5="",0,SUMPRODUCT((Plantillas!$A$2:$A$114=E$5)*(Plantillas!$D$2:$D$114=$A20)*(Plantillas!$G$2:$G$114*N(E$6)+Plantillas!$H$2:$H$114))) -> 0 | F20: =IF(F$5="",0,SUMPRODUCT((Plantillas!$A$2:$A$114=F$5)*(Plantillas!$D$2:$D$114=$A20)*(Plantillas!$G$2:$G$114*N(F$6)+Plantillas!$H$2:$H$114))) -> 0 | G20: =IF(G$5="",0,SUMPRODUCT((Plantillas!$A$2:$A$114=G$5)*(Plantillas!$D$2:$D$114=$A20)*(Plantillas!$G$2:$G$114*N(G$6)+Plantillas!$H$2:$H$114))) -> 0 | H20: =IF(H$5="",0,SUMPRODUCT((Plantillas!$A$2:$A$114=H$5)*(Plantillas!$D$2:$D$114=$A20)*(Plantillas!$G$2:$G$114*N(H$6)+Plantillas!$H$2:$H$114))) -> 0 | I20: =IF(I$5="",0,SUMPRODUCT((Plantillas!$A$2:$A$114=I$5)*(Plantillas!$D$2:$D$114=$A20)*(Plantillas!$G$2:$G$114*N(I$6)+Plantillas!$H$2:$H$114))) -> 0 | J20: =IF(J$5="",0,SUMPRODUCT((Plantillas!$A$2:$A$114=J$5)*(Plantillas!$D$2:$D$114=$A20)*(Plantillas!$G$2:$G$114*N(J$6)+Plantillas!$H$2:$H$114))) -> 0 | K20: =IF(K$5="",0,SUMPRODUCT((Plantillas!$A$2:$A$114=K$5)*(Plantillas!$D$2:$D$114=$A20)*(Plantillas!$G$2:$G$114*N(K$6)+Plantillas!$H$2:$H$114))) -> 0 | L20: =IF(L$5="",0,SUMPRODUCT((Plantillas!$A$2:$A$114=L$5)*(Plantillas!$D$2:$D$114=$A20)*(Plantillas!$G$2:$G$114*N(L$6)+Plantillas!$H$2:$H$114))) -> 0 | ... R20: =IF(R$5="",0,SUMPRODUCT((Plantillas!$A$2:$A$114=R$5)*(Plantillas!$D$2:$D$114=$A20)*(Plantillas!$G$2:$G$114*N(R$6)+Plantillas!$H$2:$H$114))) -> 0 | S20: =SUM(E20:R20) -> 0 | T20: =IF(INDEX(Partidas!$F$2:$F$99,MATCH(A20,Partidas!$A$2:$A$99,0))="","",INDEX(Partidas!$F$2:$F$99,MATCH(A20,Partidas!$A$2:$A$99,0))) -> 10 | U20: =IF(T20="",0,S20*T20) -> 0
A21: DEM-070 | B21: DEM | C21: =INDEX(Partidas!$D$2:$D$99,MATCH(A21,Partidas!$A$2:$A$99,0)) -> Desmontaje de radiador | D21: =INDEX(Partidas!$C$2:$C$99,MATCH(A21,Partidas!$A$2:$A$99,0)) -> ud | E21: =IF(E$5="",0,SUMPRODUCT((Plantillas!$A$2:$A$114=E$5)*(Plantillas!$D$2:$D$114=$A21)*(Plantillas!$G$2:$G$114*N(E$6)+Plantillas!$H$2:$H$114))) -> 0 | F21: =IF(F$5="",0,SUMPRODUCT((Plantillas!$A$2:$A$114=F$5)*(Plantillas!$D$2:$D$114=$A21)*(Plantillas!$G$2:$G$114*N(F$6)+Plantillas!$H$2:$H$114))) -> 0 | G21: =IF(G$5="",0,SUMPRODUCT((Plantillas!$A$2:$A$114=G$5)*(Plantillas!$D$2:$D$114=$A21)*(Plantillas!$G$2:$G$114*N(G$6)+Plantillas!$H$2:$H$114))) -> 0 | H21: =IF(H$5="",0,SUMPRODUCT((Plantillas!$A$2:$A$114=H$5)*(Plantillas!$D$2:$D$114=$A21)*(Plantillas!$G$2:$G$114*N(H$6)+Plantillas!$H$2:$H$114))) -> 0 | I21: =IF(I$5="",0,SUMPRODUCT((Plantillas!$A$2:$A$114=I$5)*(Plantillas!$D$2:$D$114=$A21)*(Plantillas!$G$2:$G$114*N(I$6)+Plantillas!$H$2:$H$114))) -> 0 | J21: =IF(J$5="",0,SUMPRODUCT((Plantillas!$A$2:$A$114=J$5)*(Plantillas!$D$2:$D$114=$A21)*(Plantillas!$G$2:$G$114*N(J$6)+Plantillas!$H$2:$H$114))) -> 0 | K21: =IF(K$5="",0,SUMPRODUCT((Plantillas!$A$2:$A$114=K$5)*(Plantillas!$D$2:$D$114=$A21)*(Plantillas!$G$2:$G$114*N(K$6)+Plantillas!$H$2:$H$114))) -> 0 | L21: =IF(L$5="",0,SUMPRODUCT((Plantillas!$A$2:$A$114=L$5)*(Plantillas!$D$2:$D$114=$A21)*(Plantillas!$G$2:$G$114*N(L$6)+Plantillas!$H$2:$H$114))) -> 0 | ... R21: =IF(R$5="",0,SUMPRODUCT((Plantillas!$A$2:$A$114=R$5)*(Plantillas!$D$2:$D$114=$A21)*(Plantillas!$G$2:$G$114*N(R$6)+Plantillas!$H$2:$H$114))) -> 0 | S21: =SUM(E21:R21) -> 0 | T21: =IF(INDEX(Partidas!$F$2:$F$99,MATCH(A21,Partidas!$A$2:$A$99,0))="","",INDEX(Partidas!$F$2:$F$99,MATCH(A21,Partidas!$A$2:$A$99,0))) -> 60 | U21: =IF(T21="",0,S21*T21) -> 0
A22: DEM-080 | B22: DEM | C22: =INDEX(Partidas!$D$2:$D$99,MATCH(A22,Partidas!$A$2:$A$99,0)) -> Levantado de pavimento de madera, laminado o vinílico | D22: =INDEX(Partidas!$C$2:$C$99,MATCH(A22,Partidas!$A$2:$A$99,0)) -> m2 | E22: =IF(E$5="",0,SUMPRODUCT((Plantillas!$A$2:$A$114=E$5)*(Plantillas!$D$2:$D$114=$A22)*(Plantillas!$G$2:$G$114*N(E$6)+Plantillas!$H$2:$H$114))) -> 0 | F22: =IF(F$5="",0,SUMPRODUCT((Plantillas!$A$2:$A$114=F$5)*(Plantillas!$D$2:$D$114=$A22)*(Plantillas!$G$2:$G$114*N(F$6)+Plantillas!$H$2:$H$114))) -> 0 | G22: =IF(G$5="",0,SUMPRODUCT((Plantillas!$A$2:$A$114=G$5)*(Plantillas!$D$2:$D$114=$A22)*(Plantillas!$G$2:$G$114*N(G$6)+Plantillas!$H$2:$H$114))) -> 0 | H22: =IF(H$5="",0,SUMPRODUCT((Plantillas!$A$2:$A$114=H$5)*(Plantillas!$D$2:$D$114=$A22)*(Plantillas!$G$2:$G$114*N(H$6)+Plantillas!$H$2:$H$114))) -> 0 | I22: =IF(I$5="",0,SUMPRODUCT((Plantillas!$A$2:$A$114=I$5)*(Plantillas!$D$2:$D$114=$A22)*(Plantillas!$G$2:$G$114*N(I$6)+Plantillas!$H$2:$H$114))) -> 0 | J22: =IF(J$5="",0,SUMPRODUCT((Plantillas!$A$2:$A$114=J$5)*(Plantillas!$D$2:$D$114=$A22)*(Plantillas!$G$2:$G$114*N(J$6)+Plantillas!$H$2:$H$114))) -> 0 | K22: =IF(K$5="",0,SUMPRODUCT((Plantillas!$A$2:$A$114=K$5)*(Plantillas!$D$2:$D$114=$A22)*(Plantillas!$G$2:$G$114*N(K$6)+Plantillas!$H$2:$H$114))) -> 0 | L22: =IF(L$5="",0,SUMPRODUCT((Plantillas!$A$2:$A$114=L$5)*(Plantillas!$D$2:$D$114=$A22)*(Plantillas!$G$2:$G$114*N(L$6)+Plantillas!$H$2:$H$114))) -> 0 | ... R22: =IF(R$5="",0,SUMPRODUCT((Plantillas!$A$2:$A$114=R$5)*(Plantillas!$D$2:$D$114=$A22)*(Plantillas!$G$2:$G$114*N(R$6)+Plantillas!$H$2:$H$114))) -> 0 | S22: =SUM(E22:R22) -> 0 | T22: =IF(INDEX(Partidas!$F$2:$F$99,MATCH(A22,Partidas!$A$2:$A$99,0))="","",INDEX(Partidas!$F$2:$F$99,MATCH(A22,Partidas!$A$2:$A$99,0))) -> 18 | U22: =IF(T22="",0,S22*T22) -> 0
A23: DEM-090 | B23: DEM | C23: =INDEX(Partidas!$D$2:$D$99,MATCH(A23,Partidas!$A$2:$A$99,0)) -> Picado de alicatado y solado cerámico | D23: =INDEX(Partidas!$C$2:$C$99,MATCH(A23,Partidas!$A$2:$A$99,0)) -> m2 | E23: =IF(E$5="",0,SUMPRODUCT((Plantillas!$A$2:$A$114=E$5)*(Plantillas!$D$2:$D$114=$A23)*(Plantillas!$G$2:$G$114*N(E$6)+Plantillas!$H$2:$H$114))) -> 0 | F23: =IF(F$5="",0,SUMPRODUCT((Plantillas!$A$2:$A$114=F$5)*(Plantillas!$D$2:$D$114=$A23)*(Plantillas!$G$2:$G$114*N(F$6)+Plantillas!$H$2:$H$114))) -> 0 | G23: =IF(G$5="",0,SUMPRODUCT((Plantillas!$A$2:$A$114=G$5)*(Plantillas!$D$2:$D$114=$A23)*(Plantillas!$G$2:$G$114*N(G$6)+Plantillas!$H$2:$H$114))) -> 0 | H23: =IF(H$5="",0,SUMPRODUCT((Plantillas!$A$2:$A$114=H$5)*(Plantillas!$D$2:$D$114=$A23)*(Plantillas!$G$2:$G$114*N(H$6)+Plantillas!$H$2:$H$114))) -> 0 | I23: =IF(I$5="",0,SUMPRODUCT((Plantillas!$A$2:$A$114=I$5)*(Plantillas!$D$2:$D$114=$A23)*(Plantillas!$G$2:$G$114*N(I$6)+Plantillas!$H$2:$H$114))) -> 0 | J23: =IF(J$5="",0,SUMPRODUCT((Plantillas!$A$2:$A$114=J$5)*(Plantillas!$D$2:$D$114=$A23)*(Plantillas!$G$2:$G$114*N(J$6)+Plantillas!$H$2:$H$114))) -> 0 | K23: =IF(K$5="",0,SUMPRODUCT((Plantillas!$A$2:$A$114=K$5)*(Plantillas!$D$2:$D$114=$A23)*(Plantillas!$G$2:$G$114*N(K$6)+Plantillas!$H$2:$H$114))) -> 0 | L23: =IF(L$5="",0,SUMPRODUCT((Plantillas!$A$2:$A$114=L$5)*(Plantillas!$D$2:$D$114=$A23)*(Plantillas!$G$2:$G$114*N(L$6)+Plantillas!$H$2:$H$114))) -> 0 | ... R23: =IF(R$5="",0,SUMPRODUCT((Plantillas!$A$2:$A$114=R$5)*(Plantillas!$D$2:$D$114=$A23)*(Plantillas!$G$2:$G$114*N(R$6)+Plantillas!$H$2:$H$114))) -> 0 | S23: =SUM(E23:R23) -> 0 | T23: =IF(INDEX(Partidas!$F$2:$F$99,MATCH(A23,Partidas!$A$2:$A$99,0))="","",INDEX(Partidas!$F$2:$F$99,MATCH(A23,Partidas!$A$2:$A$99,0))) -> 28 | U23: =IF(T23="",0,S23*T23) -> 0
A24: DEM-100 | B24: DEM | C24: =INDEX(Partidas!$D$2:$D$99,MATCH(A24,Partidas!$A$2:$A$99,0)) -> Desmontaje de aparato sanitario o grifería | D24: =INDEX(Partidas!$C$2:$C$99,MATCH(A24,Partidas!$A$2:$A$99,0)) -> ud | E24: =IF(E$5="",0,SUMPRODUCT((Plantillas!$A$2:$A$114=E$5)*(Plantillas!$D$2:$D$114=$A24)*(Plantillas!$G$2:$G$114*N(E$6)+Plantillas!$H$2:$H$114))) -> 0 | F24: =IF(F$5="",0,SUMPRODUCT((Plantillas!$A$2:$A$114=F$5)*(Plantillas!$D$2:$D$114=$A24)*(Plantillas!$G$2:$G$114*N(F$6)+Plantillas!$H$2:$H$114))) -> 0 | G24: =IF(G$5="",0,SUMPRODUCT((Plantillas!$A$2:$A$114=G$5)*(Plantillas!$D$2:$D$114=$A24)*(Plantillas!$G$2:$G$114*N(G$6)+Plantillas!$H$2:$H$114))) -> 0 | H24: =IF(H$5="",0,SUMPRODUCT((Plantillas!$A$2:$A$114=H$5)*(Plantillas!$D$2:$D$114=$A24)*(Plantillas!$G$2:$G$114*N(H$6)+Plantillas!$H$2:$H$114))) -> 0 | I24: =IF(I$5="",0,SUMPRODUCT((Plantillas!$A$2:$A$114=I$5)*(Plantillas!$D$2:$D$114=$A24)*(Plantillas!$G$2:$G$114*N(I$6)+Plantillas!$H$2:$H$114))) -> 0 | J24: =IF(J$5="",0,SUMPRODUCT((Plantillas!$A$2:$A$114=J$5)*(Plantillas!$D$2:$D$114=$A24)*(Plantillas!$G$2:$G$114*N(J$6)+Plantillas!$H$2:$H$114))) -> 0 | K24: =IF(K$5="",0,SUMPRODUCT((Plantillas!$A$2:$A$114=K$5)*(Plantillas!$D$2:$D$114=$A24)*(Plantillas!$G$2:$G$114*N(K$6)+Plantillas!$H$2:$H$114))) -> 0 | L24: =IF(L$5="",0,SUMPRODUCT((Plantillas!$A$2:$A$114=L$5)*(Plantillas!$D$2:$D$114=$A24)*(Plantillas!$G$2:$G$114*N(L$6)+Plantillas!$H$2:$H$114))) -> 0 | ... R24: =IF(R$5="",0,SUMPRODUCT((Plantillas!$A$2:$A$114=R$5)*(Plantillas!$D$2:$D$114=$A24)*(Plantillas!$G$2:$G$114*N(R$6)+Plantillas!$H$2:$H$114))) -> 0 | S24: =SUM(E24:R24) -> 0 | T24: =IF(INDEX(Partidas!$F$2:$F$99,MATCH(A24,Partidas!$A$2:$A$99,0))="","",INDEX(Partidas!$F$2:$F$99,MATCH(A24,Partidas!$A$2:$A$99,0))) | U24: =IF(T24="",0,S24*T24) -> 0
A25: DEM-110 | B25: DEM | C25: =INDEX(Partidas!$D$2:$D$99,MATCH(A25,Partidas!$A$2:$A$99,0)) -> Desmontaje de puerta interior | D25: =INDEX(Partidas!$C$2:$C$99,MATCH(A25,Partidas!$A$2:$A$99,0)) -> ud | E25: =IF(E$5="",0,SUMPRODUCT((Plantillas!$A$2:$A$114=E$5)*(Plantillas!$D$2:$D$114=$A25)*(Plantillas!$G$2:$G$114*N(E$6)+Plantillas!$H$2:$H$114))) -> 0 | F25: =IF(F$5="",0,SUMPRODUCT((Plantillas!$A$2:$A$114=F$5)*(Plantillas!$D$2:$D$114=$A25)*(Plantillas!$G$2:$G$114*N(F$6)+Plantillas!$H$2:$H$114))) -> 0 | G25: =IF(G$5="",0,SUMPRODUCT((Plantillas!$A$2:$A$114=G$5)*(Plantillas!$D$2:$D$114=$A25)*(Plantillas!$G$2:$G$114*N(G$6)+Plantillas!$H$2:$H$114))) -> 0 | H25: =IF(H$5="",0,SUMPRODUCT((Plantillas!$A$2:$A$114=H$5)*(Plantillas!$D$2:$D$114=$A25)*(Plantillas!$G$2:$G$114*N(H$6)+Plantillas!$H$2:$H$114))) -> 0 | I25: =IF(I$5="",0,SUMPRODUCT((Plantillas!$A$2:$A$114=I$5)*(Plantillas!$D$2:$D$114=$A25)*(Plantillas!$G$2:$G$114*N(I$6)+Plantillas!$H$2:$H$114))) -> 0 | J25: =IF(J$5="",0,SUMPRODUCT((Plantillas!$A$2:$A$114=J$5)*(Plantillas!$D$2:$D$114=$A25)*(Plantillas!$G$2:$G$114*N(J$6)+Plantillas!$H$2:$H$114))) -> 0 | K25: =IF(K$5="",0,SUMPRODUCT((Plantillas!$A$2:$A$114=K$5)*(Plantillas!$D$2:$D$114=$A25)*(Plantillas!$G$2:$G$114*N(K$6)+Plantillas!$H$2:$H$114))) -> 0 | L25: =IF(L$5="",0,SUMPRODUCT((Plantillas!$A$2:$A$114=L$5)*(Plantillas!$D$2:$D$114=$A25)*(Plantillas!$G$2:$G$114*N(L$6)+Plantillas!$H$2:$H$114))) -> 0 | ... R25: =IF(R$5="",0,SUMPRODUCT((Plantillas!$A$2:$A$114=R$5)*(Plantillas!$D$2:$D$114=$A25)*(Plantillas!$G$2:$G$114*N(R$6)+Plantillas!$H$2:$H$114))) -> 0 | S25: =SUM(E25:R25) -> 0 | T25: =IF(INDEX(Partidas!$F$2:$F$99,MATCH(A25,Partidas!$A$2:$A$99,0))="","",INDEX(Partidas!$F$2:$F$99,MATCH(A25,Partidas!$A$2:$A$99,0))) | U25: =IF(T25="",0,S25*T25) -> 0
A26: DEM-120 | B26: DEM | C26: =INDEX(Partidas!$D$2:$D$99,MATCH(A26,Partidas!$A$2:$A$99,0)) -> Levantado de instalaciones existentes | D26: =INDEX(Partidas!$C$2:$C$99,MATCH(A26,Partidas!$A$2:$A$99,0)) -> pa | E26: =IF(E$5="",0,SUMPRODUCT((Plantillas!$A$2:$A$114=E$5)*(Plantillas!$D$2:$D$114=$A26)*(Plantillas!$G$2:$G$114*N(E$6)+Plantillas!$H$2:$H$114))) -> 1 | F26: =IF(F$5="",0,SUMPRODUCT((Plantillas!$A$2:$A$114=F$5)*(Plantillas!$D$2:$D$114=$A26)*(Plantillas!$G$2:$G$114*N(F$6)+Plantillas!$H$2:$H$114))) -> 0 | G26: =IF(G$5="",0,SUMPRODUCT((Plantillas!$A$2:$A$114=G$5)*(Plantillas!$D$2:$D$114=$A26)*(Plantillas!$G$2:$G$114*N(G$6)+Plantillas!$H$2:$H$114))) -> 0 | H26: =IF(H$5="",0,SUMPRODUCT((Plantillas!$A$2:$A$114=H$5)*(Plantillas!$D$2:$D$114=$A26)*(Plantillas!$G$2:$G$114*N(H$6)+Plantillas!$H$2:$H$114))) -> 0 | I26: =IF(I$5="",0,SUMPRODUCT((Plantillas!$A$2:$A$114=I$5)*(Plantillas!$D$2:$D$114=$A26)*(Plantillas!$G$2:$G$114*N(I$6)+Plantillas!$H$2:$H$114))) -> 0 | J26: =IF(J$5="",0,SUMPRODUCT((Plantillas!$A$2:$A$114=J$5)*(Plantillas!$D$2:$D$114=$A26)*(Plantillas!$G$2:$G$114*N(J$6)+Plantillas!$H$2:$H$114))) -> 0 | K26: =IF(K$5="",0,SUMPRODUCT((Plantillas!$A$2:$A$114=K$5)*(Plantillas!$D$2:$D$114=$A26)*(Plantillas!$G$2:$G$114*N(K$6)+Plantillas!$H$2:$H$114))) -> 0 | L26: =IF(L$5="",0,SUMPRODUCT((Plantillas!$A$2:$A$114=L$5)*(Plantillas!$D$2:$D$114=$A26)*(Plantillas!$G$2:$G$114*N(L$6)+Plantillas!$H$2:$H$114))) -> 0 | ... R26: =IF(R$5="",0,SUMPRODUCT((Plantillas!$A$2:$A$114=R$5)*(Plantillas!$D$2:$D$114=$A26)*(Plantillas!$G$2:$G$114*N(R$6)+Plantillas!$H$2:$H$114))) -> 0 | S26: =SUM(E26:R26) -> 1 | T26: =IF(INDEX(Partidas!$F$2:$F$99,MATCH(A26,Partidas!$A$2:$A$99,0))="","",INDEX(Partidas!$F$2:$F$99,MATCH(A26,Partidas!$A$2:$A$99,0))) | U26: =IF(T26="",0,S26*T26) -> 0
A27: TAB | C27: Tabiquería y trasdosados | U27: =SUM(U28:U30) -> 0
A28: TAB-010 | B28: TAB | C28: =INDEX(Partidas!$D$2:$D$99,MATCH(A28,Partidas!$A$2:$A$99,0)) -> Tabique PYL 2 placas por cara con aislamiento | D28: =INDEX(Partidas!$C$2:$C$99,MATCH(A28,Partidas!$A$2:$A$99,0)) -> m2 | E28: =IF(E$5="",0,SUMPRODUCT((Plantillas!$A$2:$A$114=E$5)*(Plantillas!$D$2:$D$114=$A28)*(Plantillas!$G$2:$G$114*N(E$6)+Plantillas!$H$2:$H$114))) -> 0 | F28: =IF(F$5="",0,SUMPRODUCT((Plantillas!$A$2:$A$114=F$5)*(Plantillas!$D$2:$D$114=$A28)*(Plantillas!$G$2:$G$114*N(F$6)+Plantillas!$H$2:$H$114))) -> 0 | G28: =IF(G$5="",0,SUMPRODUCT((Plantillas!$A$2:$A$114=G$5)*(Plantillas!$D$2:$D$114=$A28)*(Plantillas!$G$2:$G$114*N(G$6)+Plantillas!$H$2:$H$114))) -> 0 | H28: =IF(H$5="",0,SUMPRODUCT((Plantillas!$A$2:$A$114=H$5)*(Plantillas!$D$2:$D$114=$A28)*(Plantillas!$G$2:$G$114*N(H$6)+Plantillas!$H$2:$H$114))) -> 0 | I28: =IF(I$5="",0,SUMPRODUCT((Plantillas!$A$2:$A$114=I$5)*(Plantillas!$D$2:$D$114=$A28)*(Plantillas!$G$2:$G$114*N(I$6)+Plantillas!$H$2:$H$114))) -> 0 | J28: =IF(J$5="",0,SUMPRODUCT((Plantillas!$A$2:$A$114=J$5)*(Plantillas!$D$2:$D$114=$A28)*(Plantillas!$G$2:$G$114*N(J$6)+Plantillas!$H$2:$H$114))) -> 0 | K28: =IF(K$5="",0,SUMPRODUCT((Plantillas!$A$2:$A$114=K$5)*(Plantillas!$D$2:$D$114=$A28)*(Plantillas!$G$2:$G$114*N(K$6)+Plantillas!$H$2:$H$114))) -> 0 | L28: =IF(L$5="",0,SUMPRODUCT((Plantillas!$A$2:$A$114=L$5)*(Plantillas!$D$2:$D$114=$A28)*(Plantillas!$G$2:$G$114*N(L$6)+Plantillas!$H$2:$H$114))) -> 0 | ... R28: =IF(R$5="",0,SUMPRODUCT((Plantillas!$A$2:$A$114=R$5)*(Plantillas!$D$2:$D$114=$A28)*(Plantillas!$G$2:$G$114*N(R$6)+Plantillas!$H$2:$H$114))) -> 0 | S28: =SUM(E28:R28) -> 0 | T28: =IF(INDEX(Partidas!$F$2:$F$99,MATCH(A28,Partidas!$A$2:$A$99,0))="","",INDEX(Partidas!$F$2:$F$99,MATCH(A28,Partidas!$A$2:$A$99,0))) -> 60 | U28: =IF(T28="",0,S28*T28) -> 0
A29: TAB-020 | B29: TAB | C29: =INDEX(Partidas!$D$2:$D$99,MATCH(A29,Partidas!$A$2:$A$99,0)) -> Trasdosado PYL 1 placa sobre perfilería con aislamiento | D29: =INDEX(Partidas!$C$2:$C$99,MATCH(A29,Partidas!$A$2:$A$99,0)) -> m2 | E29: =IF(E$5="",0,SUMPRODUCT((Plantillas!$A$2:$A$114=E$5)*(Plantillas!$D$2:$D$114=$A29)*(Plantillas!$G$2:$G$114*N(E$6)+Plantillas!$H$2:$H$114))) -> 0 | F29: =IF(F$5="",0,SUMPRODUCT((Plantillas!$A$2:$A$114=F$5)*(Plantillas!$D$2:$D$114=$A29)*(Plantillas!$G$2:$G$114*N(F$6)+Plantillas!$H$2:$H$114))) -> 0 | G29: =IF(G$5="",0,SUMPRODUCT((Plantillas!$A$2:$A$114=G$5)*(Plantillas!$D$2:$D$114=$A29)*(Plantillas!$G$2:$G$114*N(G$6)+Plantillas!$H$2:$H$114))) -> 0 | H29: =IF(H$5="",0,SUMPRODUCT((Plantillas!$A$2:$A$114=H$5)*(Plantillas!$D$2:$D$114=$A29)*(Plantillas!$G$2:$G$114*N(H$6)+Plantillas!$H$2:$H$114))) -> 0 | I29: =IF(I$5="",0,SUMPRODUCT((Plantillas!$A$2:$A$114=I$5)*(Plantillas!$D$2:$D$114=$A29)*(Plantillas!$G$2:$G$114*N(I$6)+Plantillas!$H$2:$H$114))) -> 0 | J29: =IF(J$5="",0,SUMPRODUCT((Plantillas!$A$2:$A$114=J$5)*(Plantillas!$D$2:$D$114=$A29)*(Plantillas!$G$2:$G$114*N(J$6)+Plantillas!$H$2:$H$114))) -> 0 | K29: =IF(K$5="",0,SUMPRODUCT((Plantillas!$A$2:$A$114=K$5)*(Plantillas!$D$2:$D$114=$A29)*(Plantillas!$G$2:$G$114*N(K$6)+Plantillas!$H$2:$H$114))) -> 0 | L29: =IF(L$5="",0,SUMPRODUCT((Plantillas!$A$2:$A$114=L$5)*(Plantillas!$D$2:$D$114=$A29)*(Plantillas!$G$2:$G$114*N(L$6)+Plantillas!$H$2:$H$114))) -> 0 | ... R29: =IF(R$5="",0,SUMPRODUCT((Plantillas!$A$2:$A$114=R$5)*(Plantillas!$D$2:$D$114=$A29)*(Plantillas!$G$2:$G$114*N(R$6)+Plantillas!$H$2:$H$114))) -> 0 | S29: =SUM(E29:R29) -> 0 | T29: =IF(INDEX(Partidas!$F$2:$F$99,MATCH(A29,Partidas!$A$2:$A$99,0))="","",INDEX(Partidas!$F$2:$F$99,MATCH(A29,Partidas!$A$2:$A$99,0))) -> 40 | U29: =IF(T29="",0,S29*T29) -> 0
A30: TAB-030 | B30: TAB | C30: =INDEX(Partidas!$D$2:$D$99,MATCH(A30,Partidas!$A$2:$A$99,0)) -> Trasdosado PYL 1 placa directo | D30: =INDEX(Partidas!$C$2:$C$99,MATCH(A30,Partidas!$A$2:$A$99,0)) -> m2 | E30: =IF(E$5="",0,SUMPRODUCT((Plantillas!$A$2:$A$114=E$5)*(Plantillas!$D$2:$D$114=$A30)*(Plantillas!$G$2:$G$114*N(E$6)+Plantillas!$H$2:$H$114))) -> 0 | F30: =IF(F$5="",0,SUMPRODUCT((Plantillas!$A$2:$A$114=F$5)*(Plantillas!$D$2:$D$114=$A30)*(Plantillas!$G$2:$G$114*N(F$6)+Plantillas!$H$2:$H$114))) -> 0 | G30: =IF(G$5="",0,SUMPRODUCT((Plantillas!$A$2:$A$114=G$5)*(Plantillas!$D$2:$D$114=$A30)*(Plantillas!$G$2:$G$114*N(G$6)+Plantillas!$H$2:$H$114))) -> 0 | H30: =IF(H$5="",0,SUMPRODUCT((Plantillas!$A$2:$A$114=H$5)*(Plantillas!$D$2:$D$114=$A30)*(Plantillas!$G$2:$G$114*N(H$6)+Plantillas!$H$2:$H$114))) -> 0 | I30: =IF(I$5="",0,SUMPRODUCT((Plantillas!$A$2:$A$114=I$5)*(Plantillas!$D$2:$D$114=$A30)*(Plantillas!$G$2:$G$114*N(I$6)+Plantillas!$H$2:$H$114))) -> 0 | J30: =IF(J$5="",0,SUMPRODUCT((Plantillas!$A$2:$A$114=J$5)*(Plantillas!$D$2:$D$114=$A30)*(Plantillas!$G$2:$G$114*N(J$6)+Plantillas!$H$2:$H$114))) -> 0 | K30: =IF(K$5="",0,SUMPRODUCT((Plantillas!$A$2:$A$114=K$5)*(Plantillas!$D$2:$D$114=$A30)*(Plantillas!$G$2:$G$114*N(K$6)+Plantillas!$H$2:$H$114))) -> 0 | L30: =IF(L$5="",0,SUMPRODUCT((Plantillas!$A$2:$A$114=L$5)*(Plantillas!$D$2:$D$114=$A30)*(Plantillas!$G$2:$G$114*N(L$6)+Plantillas!$H$2:$H$114))) -> 0 | ... R30: =IF(R$5="",0,SUMPRODUCT((Plantillas!$A$2:$A$114=R$5)*(Plantillas!$D$2:$D$114=$A30)*(Plantillas!$G$2:$G$114*N(R$6)+Plantillas!$H$2:$H$114))) -> 0 | S30: =SUM(E30:R30) -> 0 | T30: =IF(INDEX(Partidas!$F$2:$F$99,MATCH(A30,Partidas!$A$2:$A$99,0))="","",INDEX(Partidas!$F$2:$F$99,MATCH(A30,Partidas!$A$2:$A$99,0))) -> 30 | U30: =IF(T30="",0,S30*T30) -> 0
A31: TEC | C31: Falsos techos y molduras | U31: =SUM(U32:U36) -> 2772
